Workbook

Sheet 滚动稳健标准化季频
B1: GDP:不变价:当季同比 | C1: 中国:工业产能利用率:当季值
A2: 46022 | B2: 4.5 | C2: 74.9
A3: 45930 | B3: 4.8 | C3: 74.6
A4: 45838 | B4: 5.2 | C4: 74
A5: 45747 | B5: 5.4 | C5: 74.1
A6: 45657 | B6: 5.4 | C6: 76.2
A7: 45565 | B7: 4.6 | C7: 75.1
A8: 45473 | B8: 4.7 | C8: 74.9
A9: 45382 | B9: 5.3 | C9: 73.6
A10: 45291 | B10: 5.3 | C10: 75.903011
A11: 45199 | B11: 5 | C11: 75.6
A12: 45107 | B12: 6.5 | C12: 74.5
A13: 45016 | B13: 4.7 | C13: 74.3
... A53: 41364 | B53: 7.9 | C53: 75.3
A54: 41274 | B54: 8.1
A55: 41182 | B55: 7.5
A56: 41090 | B56: 7.7
A57: 40999 | B57: 8.1
A58: 40908 | B58: 8.7
A59: 40816 | B59: 9.3
A60: 40724 | B60: 9.9
A61: 40633 | B61: 10.1
A62: 40543 | B62: 9.9
A63: 40451 | B63: 9.9
A64: 40359 | B64: 10.7
A65: 40268 | B65: 12.2

Sheet 季频数据发布日期
B1: GDP同比 | C1: 产能利用率
A2: 46022 | B2: 46041 | C2: 46041
A3: 45930 | B3: 45950 | C3: 45950
A4: 45838 | B4: 45853 | C4: 45853
A5: 45747 | B5: 45763 | C5: 45763
A6: 45657 | B6: 45674 | C6: 45674
A7: 45565 | B7: 45583 | C7: 45583
A8: 45473 | B8: 2024-07-16 | C8: 2024-07-16
A9: 45382 | B9: 2024-04-17 | C9: 2024-04-17
A10: 45291 | B10: 2024-01-18 | C10: 2024-01-18
A11: 45199 | B11: 2023-10-19 | C11: 2023-10-19
A12: 45107 | B12: 2023-07-15 | C12: 2023-07-15
A13: 45016 | B13: 2023-04-19 | C13: 2023-04-19
A14: 44926 | B14: 2023-01-18 | C14: 2023-01-18
A15: 44834 | B15: 2022-10-24 | C15: 2022-10-24
A16: 44742 | B16: 2022-07-16 | C16: 2022-07-16
A17: 44651 | B17: 2022-04-19 | C17: 2022-04-19
A18: 44561 | B18: 2022-01-18 | C18: 2022-01-18
A19: 44469 | B19: 2021-10-19 | C19: 2021-10-19
... A45: 42094 | B45: 2015-04-16 | C45: 2015-04-16
A46: 42004 | B46: 42025 | C46: 42025
A47: 41912 | B47: 41934 | C47: 41934
A48: 41820 | B48: 41837 | C48: 41837
A49: 41729 | B49: 41746 | C49: 41746
A50: 41639 | B50: 41660 | C50: 41660
A51: 41547 | B51: 41566 | C51: 41566
A52: 41455 | B52: 41471 | C52: 41471
A53: 41364 | B53: 41380 | C53: 41380
A54: 41274 | B54: 41293 | C54: 41293
A55: 41182 | B55: 41205 | C55: 41205
A56: 41090 | B56: 41103 | C56: 41103
A57: 40999 | B57: 41008 | C57: 41008
... A65: 40268 | B65: 40283 | C65: 40283

Sheet 滚动稳健标准化月频
B1: 工业增加值同比 | C1: 社会消费品零售总额同比 | D1: 固定资产投资完成额:基础设施建设:累计同比 | E1: 房地产开发投资完成额:累计同比 | F1: CPI同比 | G1: PPI同比 | H1: M2同比 | I1: PMI-50 | J1: 出口金额:当月同比 | K1: 进口金额:当月同比 | L1: 商品房销售面积:累计同比 | M1: 70个大中城市:房屋销售价格指数:新建商品住宅:当月同比 | N1: 社融同比 | O1: M1旧口径 | P1: 商业银行托管同比 | Q1: 广义基金托管同比 | R1: 证券公司托管同比 | S1: 保险托管同比
A2: 46022 | B2: 5.9 | C2: 0.9 | D2: -1.48 | E2: -17.2 | F2: 0.8 | G2: -1.9 | H2: 8.5 | I2: 0.1 | J2: 6.6 | K2: 5.7 | L2: -8.7 | M2: -3 | N2: 8.3 | O2: 2.0337177 | P2: 10.699649 | Q2: 10.447595 | R2: 10.699649 | S2: 11.523763
A3: 45991 | B3: 6 | C3: 1.3 | D3: 0.13 | E3: -15.9 | F3: 0.7 | G3: -2.2 | H3: 8 | I3: -0.8 | J3: 5.9 | K3: 1.9 | L3: -7.8 | M3: -2.8 | N3: 8.5 | O3: 3.7767342 | P3: 9.96805 | Q3: 16.034983 | R3: -5.4740288 | S3: 10.478727
A4: 45961 | B4: 6.1 | C4: 2.9 | D4: 1.51 | E4: -14.7 | F4: 0.2 | G4: -2.1 | H4: 8.2 | I4: -1 | J4: -1.1 | K4: 1 | L4: -6.8 | M4: -2.6 | N4: 8.5 | O4: 5.3708974 | P4: 8.5902049 | Q4: 19.379329 | R4: 2.1788192 | S4: 9.7894459
A5: 45930 | B5: 6.2 | C5: 3 | D5: 3.34 | E5: -13.9 | F5: -0.3 | G5: -2.3 | H5: 8.4 | I5: -0.2 | J5: 8.3 | K5: 7.4 | L5: -5.5 | M5: -2.7 | N5: 8.7 | O5: 6.2475147 | P5: 9.8730293 | Q5: 16.796831 | R5: -1.5955517 | S5: 12.041835
A6: 45900 | B6: 6.2 | C6: 3.4 | D6: 5.42 | E6: -12.9 | F6: -0.4 | G6: -2.9 | H6: 8.8 | I6: -0.6 | J6: 4.4 | K6: 1.3 | L6: -4.7 | M6: -3 | N6: 8.8 | O6: 5.7873906 | P6: 10.947557 | Q6: 18.696161 | R6: 0.13670903 | S6: 12.107477
A7: 45869 | B7: 6.3 | C7: 3.7 | D7: 7.29 | E7: -12 | F7: 0 | G7: -3.6 | H7: 8.8 | I7: -0.7 | J7: 7.2 | K7: 4.1 | L7: -4 | M7: -3.4 | N7: 9 | O7: 4.8925303 | P7: 11.263827 | Q7: 18.472467 | R7: 1.9077217 | S7: 12.342808
A8: 45838 | B8: 6.4 | C8: 4.8 | D8: 8.9 | E8: -11.2 | F8: 0.1 | G8: -3.6 | H8: 8.3 | I8: -0.3 | J8: 5.8 | K8: 1.1 | L8: -3.5 | M8: -3.7 | N8: 8.9 | O8: 3.1413411 | P8: 9.159834 | Q8: 21.137358 | R8: 7.6424667 | S8: 11.877984
A9: 45808 | B9: 6.3 | C9: 6.4 | D9: 10.42 | E9: -10.7 | F9: -0.1 | G9: -3.3 | H9: 7.9 | I9: -0.5 | J9: 4.8 | K9: -3.4 | L9: -2.9 | M9: -4.1 | N9: 8.7 | O9: 0.73960821 | P9: 8.8462778 | Q9: 26.298124 | R9: 8.5058697 | S9: 16.145584
A10: 45777 | B10: 6.4 | C10: 5.1 | D10: 10.85 | E10: -10.3 | F10: -0.1 | G10: -2.7 | H10: 8 | I10: -1 | J10: 8.1 | K10: -0.2 | L10: -2.8 | M10: -4.5 | N10: 8.7 | O10: -1.0194591 | P10: 8.1598741 | Q10: 26.666418 | R10: 15.820812 | S10: 19.016841
A11: 45747 | B11: 6.5 | C11: 5.9 | D11: 11.5 | E11: -9.9 | F11: -0.1 | G11: -2.5 | H11: 7 | I11: 0.5 | J11: 12.4 | K11: -4.3 | L11: -3 | M11: -5 | N11: 8.4 | O11: -0.82758331 | P11: 7.2527487 | Q11: 26.878507 | R11: 2.049759 | S11: 20.856684
A12: 45716 | B12: 5.9 | C12: 4 | D12: 9.95 | E12: -9.8 | F12: -0.7 | G12: -2.2 | H12: 7 | I12: 0.2 | J12: -3 | K12: 1.5 | L12: -5.1 | M12: -5.2 | N12: 8.2 | O12: -2.5016335 | P12: 8.0077588 | Q12: 20.47689 | R12: -3.3971229 | S12: 19.800815
A13: 45688 | F13: 0.5 | G13: -2.3 | H13: 7 | I13: -0.9 | J13: 6 | K13: -16.5 | M13: -5.4 | N13: 8 | O13: -5.6892337 | P13: 6.6180465 | Q13: 21.875279 | R13: -3.9444617 | S13: 16.22303
A14: 45657 | B14: 5.8 | C14: 3.7 | D14: 9.19 | E14: -10.6 | F14: 0.1 | G14: -2.3 | H14: 7.3 | I14: 0.1 | J14: 10.7 | K14: 1 | L14: -12.9 | M14: -5.7 | N14: 8 | O14: -1.408156 | P14: 7.9805223 | Q14: 25.485484 | R14: -1.6210693 | S14: 15.994563
A15: 45626 | B15: 5.8 | C15: 3 | D15: 9.39 | E15: -10.4 | F15: 0.2 | G15: -2.5 | H15: 7.1 | I15: 0.3 | J15: 6.6 | K15: -4 | L15: -14.3 | M15: -6.1 | N15: 7.8 | O15: -3.6986424 | P15: 8.6761002 | Q15: 20.132138 | R15: 3.9107764 | S15: 16.150596
A16: 45596 | B16: 5.8 | C16: 4.8 | D16: 9.35 | E16: -10.3 | F16: 0.3 | G16: -2.9 | H16: 7.5 | I16: 0.1 | J16: 12.7 | K16: -2.4 | L16: -15.8 | M16: -6.2 | N16: 7.8 | O16: -6.1269958 | P16: 10.273363 | Q16: 16.213508 | R16: 3.9810565 | S16: 16.539718
A17: 45565 | B17: 5.8 | C17: 3.2 | D17: 9.26 | E17: -10.1 | F17: 0.4 | G17: -2.8 | H17: 6.8 | I17: -0.2 | J17: 2.4 | K17: 0.2 | L17: -17.1 | M17: -6.1 | N17: 8 | O17: -7.400336 | P17: 11.713019 | Q17: 15.262087 | R17: 2.4290872 | S17: 16.546661
A18: 45535 | B18: 5.8 | C18: 2.1 | D18: 7.87 | E18: -10.2 | F18: 0.6 | G18: -1.8 | H18: 6.3 | I18: -0.9 | J18: 8.6 | K18: 0.2 | L18: -18 | M18: -5.7 | N18: 8.1 | O18: -7.2617872 | P18: 11.74941 | Q18: 10.894768 | R18: 5.9387486 | S18: 15.684167
A19: 45504 | B19: 5.9 | C19: 2.7 | D19: 8.14 | E19: -10.2 | F19: 0.5 | G19: -0.8 | H19: 6.3 | I19: -0.6 | J19: 6.9 | K19: 6.8 | L19: -18.6 | M19: -5.3 | N19: 8.2 | O19: -6.6333616 | P19: 11.410724 | Q19: 13.044991 | R19: 8.2460315 | S19: 16.363089
A20: 45473 | B20: 6 | C20: 2 | D20: 7.7 | E20: -10.1 | F20: 0.2 | G20: -0.8 | H20: 6.2 | I20: -0.5 | J20: 8.5 | K20: -2.5 | L20: -19 | M20: -4.9 | N20: 8.1 | O20: -5.0294979 | P20: 12.27401 | Q20: 12.789793 | R20: 1.8571329 | S20: 14.405241
A21: 45443 | B21: 6.2 | C21: 3.7 | D21: 6.679178 | E21: -10.1 | F21: 0.3 | G21: -1.4 | H21: 7 | I21: -0.5 | J21: 7.4 | K21: 2 | L21: -20.3 | M21: -4.3 | N21: 8.4 | O21: -4.2073876 | P21: 12.458108 | Q21: 9.2025089 | R21: 3.8349613 | S21: 17.500432
A22: 45412 | B22: 6.3 | C22: 2.3 | D22: 7.783003 | E22: -9.8 | F22: 0.3 | G22: -2.5 | H22: 7.2 | I22: 0.4 | J22: 1.3 | K22: 8.3 | L22: -20.2 | M22: -3.5 | N22: 8.3 | O22: -1.4476585 | P22: 11.303859 | Q22: 7.8501127 | R22: 1.8546229 | S22: 17.293061
A23: 45382 | B23: 6.1 | C23: 3.1 | D23: 8.754397 | E23: -9.5 | F23: 0.1 | G23: -2.8 | H23: 8.3 | I23: 0.8 | J23: -7.6 | K23: -2 | L23: -19.4 | M23: -2.7 | N23: 8.7 | O23: 1.1428597 | P23: 11.901275 | Q23: 7.7602431 | R23: 7.585381 | S23: 14.428907
A24: 45351 | B24: 7 | C24: 5.5 | D24: 8.955393 | E24: -9 | F24: 0.7 | G24: -2.7 | H24: 8.7 | I24: -0.9 | J24: 6.3 | K24: -8 | L24: -20.5 | M24: -1.9 | N24: 9 | O24: 1.2124761 | P24: 11.371534 | Q24: 7.8711607 | R24: 16.878664 | S24: 15.882845
A25: 45322 | F25: -0.8 | G25: -2.5 | H25: 8.7 | I25: -0.8 | J25: 7.7 | K25: 15.6 | M25: -1.2 | N25: 9.5 | O25: 5.9497676 | P25: 13.260741 | Q25: 5.710548 | R25: 20.593313 | S25: 16.354411
A26: 45291 | B26: 4.6 | C26: 7.4 | D26: 8.24 | E26: -9.6 | F26: -0.3 | G26: -2.7 | H26: 9.7 | I26: -1 | J26: 2.147524 | K26: 0.287854 | L26: -8.5 | M26: -0.9 | N26: 9.5 | O26: 1.3202446 | P26: 14.166638 | Q26: 1.3229547 | R26: 17.892917 | S26: 16.354831
A27: 45260 | B27: 4.3 | C27: 10.1 | D27: 7.9642 | E27: -9.4 | F27: -0.5 | G27: -3 | H27: 10 | I27: -0.6 | J27: 0.693013 | K27: -0.563534 | L27: -8 | M27: -0.7 | N27: 9.4 | O27: 1.3283709 | P27: 15.394724 | Q27: -2.4728486 | R27: 21.932331 | S27: 16.123432
A28: 45230 | B28: 4.1 | C28: 7.6 | D28: 8.27 | E28: -9.3 | F28: -0.2 | G28: -2.6 | H28: 10.3 | I28: -0.5 | J28: -6.612764 | K28: 3.034364 | L28: -7.8 | M28: -0.6 | N28: 9.3 | O28: 1.8961324 | P28: 16.377643 | Q28: -6.4372468 | R28: 21.122868 | S28: 16.437054
A29: 45199 | B29: 4 | C29: 5.5 | D29: 8.64 | E29: -9.1 | F29: 0 | G29: -2.5 | H29: 10.3 | I29: 0.2 | J29: -6.846969 | K29: -6.251377 | L29: -7.5 | M29: -0.6 | N29: 9 | O29: 2.0929637 | P29: 14.504944 | Q29: -6.3689529 | R29: 23.111007 | S29: 15.029226
A30: 45169 | B30: 3.9 | C30: 4.6 | D30: 8.959009 | E30: -8.8 | F30: 0.1 | G30: -3 | H30: 10.6 | I30: -0.3 | J30: -8.552899 | K30: -7.186193 | L30: -7.1 | M30: -0.6 | N30: 9 | O30: 2.2544975 | P30: 14.187769 | Q30: -2.8733033 | R30: 19.402642 | S30: 16.809046
A31: 45138 | B31: 3.8 | C31: 2.5 | D31: 9.410929 | E31: -8.5 | F31: -0.3 | G31: -4.4 | H31: 10.7 | I31: -0.7 | J31: -14.256267 | K31: -12.145378 | L31: -6.5 | M31: -0.6 | N31: 8.9 | O31: 2.3248487 | P31: 12.820627 | Q31: -3.1908495 | R31: 17.703097 | S31: 14.909369
A32: 45107 | B32: 3.8 | C32: 3.1 | D32: 10.15 | E32: -7.9 | F32: 0 | G32: -5.4 | H32: 11.3 | I32: -1 | J32: -12.377592 | K32: -7.075619 | L32: -5.3 | M32: -0.4 | N32: 9 | O32: 3.146719 | P32: 11.516213 | Q32: -3.788913 | R32: 22.912451 | S32: 16.077857
A33: 45077 | B33: 3.6 | C33: 12.7 | D33: 9.53 | E33: -7.2 | F33: 0.2 | G33: -4.6 | H33: 11.6 | I33: -1.2 | J33: -7.561723 | K33: -5.27686 | L33: -0.9 | M33: -0.5 | N33: 9.5 | O33: 4.6729358 | P33: 13.839501 | Q33: -2.407132 | R33: 16.195374 | S33: 16.924573
A34: 45046 | B34: 3.6 | C34: 18.4 | D34: 9.8 | E34: -6.2 | F34: 0.1 | G34: -3.6 | H34: 12.4 | I34: -0.8 | J34: 7.105757 | K34: -8.822314 | L34: -0.4 | M34: -0.7 | N34: 10 | O34: 5.2854077 | P34: 14.746352 | Q34: -2.5554125 | R34: 20.911411 | S34: 17.063757
A35: 45016 | B35: 3 | C35: 10.6 | D35: 10.82 | E35: -5.8 | F35: 0.7 | G35: -2.5 | H35: 12.7 | I35: 1.9 | J35: 10.84 | K35: -2.018112 | L35: -1.8 | M35: -1.4 | N35: 10 | O35: 5.1151266 | P35: 14.516471 | Q35: -4.3492631 | R35: 17.879691 | S35: 18.688837
A36: 44985 | B36: 2.4 | C36: 3.5 | D36: 12.18 | E36: -5.7 | F36: 1 | G36: -1.4 | H36: 12.9 | I36: 2.6 | J36: -2.86551 | K36: 4.241862 | L36: -3.6 | M36: -1.9 | N36: 9.9 | O36: 5.8439386 | P36: 15.649806 | Q36: -3.3241251 | R36: 22.984936 | S36: 15.696755
A37: 44957 | F37: 2.1 | G37: -0.8 | H37: 12.6 | I37: 0.1 | J37: -12.023126 | K37: -21.078238 | M37: -2.3 | N37: 9.4 | O37: 6.7368543 | P37: 14.917961 | Q37: -0.94058148 | R37: 18.169752 | S37: 14.945609
A38: 44926 | B38: 3.6 | C38: -1.8 | D38: 11.52 | E38: -10 | F38: 1.8 | G38: -0.7 | H38: 11.8 | I38: -3 | J38: -12.59 | K38: -7.53 | L38: -24.3 | M38: -2.3 | N38: 9.6 | O38: 3.7426301 | P38: 14.546514 | Q38: 2.501316 | R38: 17.739632 | S38: 13.275508
A39: 44895 | B39: 3.8 | C39: -5.9 | D39: 11.65 | E39: -9.8 | F39: 1.6 | G39: -1.3 | H39: 12.4 | I39: -2 | J39: -10.38 | K39: -11.14 | L39: -23.3 | M39: -2.3 | N39: 10 | O39: 4.6370812 | P39: 14.493838 | Q39: 5.8238041 | R39: 11.851642 | S39: 14.598686
A40: 44865 | B40: 4 | C40: -0.5 | D40: 11.39 | E40: -8.8 | F40: 2.1 | G40: -1.3 | H40: 11.8 | I40: -0.8 | J40: -1.84 | K40: -1.31 | L40: -22.3 | M40: -2.4 | N40: 10.3 | O40: 5.7594489 | P40: 13.475943 | Q40: 14.674844 | R40: 15.961803 | S40: 15.041913
...

Sheet 月频数据发布日期
B1: 工业增加值同比 | C1: 社会消费品零售总额同比 | D1: 固定资产投资完成额:基础设施建设:累计同比 | E1: 房地产开发投资完成额:累计同比 | F1: CPI同比 | G1: PPI同比 | H1: 社融同比 | I1: M1同比 | J1: M2同比 | K1: PMI-50 | L1: 进口金额 | M1: 出口金额 | N1: 商业银行托管同比 | O1: 广义基金托管同比 | P1: 证券公司托管同比 | Q1: 保险托管同比
A2: 46022 | B2: 46041 | C2: 46041 | D2: 46041 | E2: 46041 | F2: 46031 | G2: 46031 | H2: 46037 | I2: 46037 | J2: 46037 | K2: 46022 | L2: 46036 | M2: 46036 | N2: 46037 | O2: 46037 | P2: 46037 | Q2: 46037
A3: 45991 | B3: 46006 | C3: 46006 | D3: 46006 | E3: 46006 | F3: 46001 | G3: 46001 | H3: 46006 | I3: 46006 | J3: 46006 | K3: 45991 | L3: 45999 | M3: 45999 | N3: 46010 | O3: 46010 | P3: 46010 | Q3: 46010
A4: 45961 | B4: 45975 | C4: 45975 | D4: 45975 | E4: 45975 | F4: 45970 | G4: 45970 | H4: 45974 | I4: 45974 | J4: 45974 | K4: 45961 | L4: 45968 | M4: 45968 | N4: 45978 | O4: 45978 | P4: 45978 | Q4: 45978
A5: 45930 | B5: 45950 | C5: 45950 | D5: 45950 | E5: 45950 | F5: 45945 | G5: 45945 | H5: 45945 | I5: 45945 | J5: 45945 | K5: 45930 | L5: 45943 | M5: 45943 | N5: 45952 | O5: 45952 | P5: 45952 | Q5: 45952
A6: 45900 | B6: 45915 | C6: 45915 | D6: 45915 | E6: 45915 | F6: 45910 | G6: 45910 | H6: 45912 | I6: 45912 | J6: 45912 | K6: 45900 | L6: 45908 | M6: 45908 | N6: 45919 | O6: 45919 | P6: 45919 | Q6: 45919
A7: 45869 | B7: 45884 | C7: 45884 | D7: 45884 | E7: 45884 | F7: 45878 | G7: 45878 | H7: 45882 | I7: 45882 | J7: 45882 | K7: 45869 | L7: 45876 | M7: 45876 | N7: 45887 | O7: 45887 | P7: 45887 | Q7: 45887
A8: 45838 | B8: 45853 | C8: 45853 | D8: 45853 | E8: 45853 | F8: 45847 | G8: 45847 | H8: 45852 | I8: 45852 | J8: 45852 | K8: 45838 | L8: 45852 | M8: 45852 | N8: 45861 | O8: 45861 | P8: 45861 | Q8: 45861
A9: 45808 | B9: 45824 | C9: 45824 | D9: 45824 | E9: 45824 | F9: 45817 | G9: 45817 | H9: 45821 | I9: 45821 | J9: 45821 | K9: 45808 | L9: 45824 | M9: 45824 | N9: 45826 | O9: 45826 | P9: 45826 | Q9: 45826
A10: 45777 | B10: 45796 | C10: 45796 | D10: 45796 | E10: 45796 | F10: 45787 | G10: 45787 | H10: 45791 | I10: 45791 | J10: 45791 | K10: 45777 | L10: 45786 | M10: 45786 | N10: 45798 | O10: 45798 | P10: 45798 | Q10: 45798
A11: 45747 | B11: 45763 | C11: 45763 | D11: 45763 | E11: 45763 | F11: 45757 | G11: 45757 | H11: 45760 | I11: 45760 | J11: 45760 | K11: 45747 | L11: 45761 | M11: 45761 | N11: 45770 | O11: 45770 | P11: 45770 | Q11: 45770
A12: 45716 | B12: 45733 | C12: 45733 | D12: 45733 | E12: 45733 | F12: 45725 | G12: 45725 | H12: 45730 | I12: 45730 | J12: 45730 | K12: 45717 | L12: 45734 | M12: 45734 | N12: 45735 | O12: 45735 | P12: 45735 | Q12: 45735
A13: 45688 | B13: 45733 | C13: 45733 | D13: 45733 | E13: 45733 | F13: 45697 | G13: 45697 | H13: 45702 | I13: 45702 | J13: 45702 | K13: 45684 | L13: 45734 | M13: 45734 | N13: 45707 | O13: 45707 | P13: 45707 | Q13: 45707
A14: 45657 | B14: 45674 | C14: 45674 | D14: 45674 | E14: 45674 | F14: 45667 | G14: 45667 | H14: 45671 | I14: 45671 | J14: 45671 | K14: 45657 | L14: 45675 | M14: 45675 | N14: 45675 | O14: 45675 | P14: 45675 | Q14: 45675
A15: 45626 | B15: 45642 | C15: 45642 | D15: 45642 | E15: 45642 | F15: 45635 | G15: 45635 | H15: 45639 | I15: 45639 | J15: 45639 | K15: 45626 | L15: 45644 | M15: 45644 | N15: 2024-12-20 | O15: 2024-12-20 | P15: 2024-12-20 | Q15: 2024-12-20
A16: 45596 | B16: 45611 | C16: 45611 | D16: 45611 | E16: 45611 | F16: 45605 | G16: 45605 | H16: 45607 | I16: 45607 | J16: 45607 | K16: 45596 | L16: 45614 | M16: 45614 | N16: 2024-11-20 | O16: 2024-11-20 | P16: 2024-11-20 | Q16: 2024-11-20
A17: 45565 | B17: 45583 | C17: 45583 | D17: 45583 | E17: 45583 | F17: 45578 | G17: 45578 | H17: 45579 | I17: 45579 | J17: 45579 | K17: 45565 | L17: 45583 | M17: 45583 | N17: 2024-10-20 | O17: 2024-10-20 | P17: 2024-10-20 | Q17: 2024-10-20
A18: 45535 | B18: 45549 | C18: 45549 | D18: 45549 | E18: 45549 | F18: 2024-09-09 | G18: 2024-09-09 | H18: 2024-09-13 | I18: 2024-09-13 | J18: 2024-09-13 | K18: 45535 | L18: 45553 | M18: 45553 | N18: 2024-09-20 | O18: 2024-09-20 | P18: 2024-09-20 | Q18: 2024-09-20
A19: 45504 | B19: 45519 | C19: 45519 | D19: 45519 | E19: 45519 | F19: 2024-08-09 | G19: 2024-08-09 | H19: 2024-08-13 | I19: 2024-08-13 | J19: 2024-08-13 | K19: 45504 | L19: 45522 | M19: 45522 | N19: 2024-08-20 | O19: 2024-08-20 | P19: 2024-08-20 | Q19: 2024-08-20
A20: 45473 | B20: 45488 | C20: 45488 | D20: 45488 | E20: 45488 | F20: 2024-07-10 | G20: 2024-07-10 | H20: 2024-07-12 | I20: 2024-07-12 | J20: 2024-07-12 | K20: 45473 | L20: 45491 | M20: 45491 | N20: 2024-07-20 | O20: 2024-07-20 | P20: 2024-07-20 | Q20: 2024-07-20
A21: 45443 | B21: 45460 | C21: 45460 | D21: 45460 | E21: 45460 | F21: 2024-06-12 | G21: 2024-06-12 | H21: 2024-06-14 | I21: 2024-06-14 | J21: 2024-06-14 | K21: 45443 | L21: 45461 | M21: 45461 | N21: 2024-06-20 | O21: 2024-06-20 | P21: 2024-06-20 | Q21: 2024-06-20
A22: 45412 | B22: 45429 | C22: 45429 | D22: 45429 | E22: 45429 | F22: 2024-05-11 | G22: 2024-05-11 | H22: 2024-05-11 | I22: 2024-05-11 | J22: 2024-05-11 | K22: 45412 | L22: 45430 | M22: 45430 | N22: 2024-05-20 | O22: 2024-05-20 | P22: 2024-05-20 | Q22: 2024-05-20
A23: 45382 | B23: 45398 | C23: 45398 | D23: 45398 | E23: 45398 | F23: 2024-04-11 | G23: 2024-04-11 | H23: 2024-04-12 | I23: 2024-04-12 | J23: 2024-04-12 | K23: 45382 | L23: 45400 | M23: 45400 | N23: 2024-04-20 | O23: 2024-04-20 | P23: 2024-04-20 | Q23: 2024-04-20
A24: 45351 | B24: 45369 | C24: 45369 | D24: 45369 | E24: 45369 | F24: 2024-03-09 | G24: 2024-03-09 | H24: 2024-03-15 | I24: 2024-03-15 | J24: 2024-03-15 | K24: 45352 | L24: 45369 | M24: 45369 | N24: 2024-03-20 | O24: 2024-03-20 | P24: 2024-03-20 | Q24: 2024-03-20
A25: 45322 | B25: 45309 | C25: 45309 | D25: 45309 | E25: 45309 | F25: 2024-02-08 | G25: 2024-02-08 | H25: 2024-02-09 | I25: 2024-02-09 | J25: 2024-02-09 | K25: 45322 | L25: 45369 | M25: 45369 | N25: 2024-02-20 | O25: 2024-02-20 | P25: 2024-02-20 | Q25: 2024-02-20
A26: 45291 | B26: 45308 | C26: 45308 | D26: 45308 | E26: 45308 | F26: 2024-01-12 | G26: 2024-01-12 | H26: 2024-01-12 | I26: 2024-01-12 | J26: 2024-01-12 | K26: 45291 | L26: 45309 | M26: 45309 | N26: 2024-01-20 | O26: 2024-01-20 | P26: 2024-01-20 | Q26: 2024-01-20
A27: 45260 | B27: 45275 | C27: 45275 | D27: 45275 | E27: 45275 | F27: 2023-12-09 | G27: 2023-12-09 | H27: 2023-12-13 | I27: 2023-12-13 | J27: 2023-12-13 | K27: 45260 | L27: 45278 | M27: 45278 | N27: 2023-12-20 | O27: 2023-12-20 | P27: 2023-12-20 | Q27: 2023-12-20
A28: 45230 | B28: 2023-11-15 | C28: 2023-11-15 | D28: 2023-11-15 | E28: 2023-11-15 | F28: 2023-11-09 | G28: 2023-11-09 | H28: 2023-11-13 | I28: 2023-11-13 | J28: 2023-11-13 | K28: 45230 | L28: 45248 | M28: 45248 | N28: 2023-11-20 | O28: 2023-11-20 | P28: 2023-11-20 | Q28: 2023-11-20
A29: 45199 | B29: 2023-10-18 | C29: 2023-10-18 | D29: 2023-10-18 | E29: 2023-10-18 | F29: 2023-10-13 | G29: 2023-10-13 | H29: 2023-10-13 | I29: 2023-10-13 | J29: 2023-10-13 | K29: 45199 | L29: 45217 | M29: 45217 | N29: 2023-10-20 | O29: 2023-10-20 | P29: 2023-10-20 | Q29: 2023-10-20
A30: 45169 | B30: 2023-09-15 | C30: 2023-09-15 | D30: 2023-09-15 | E30: 2023-09-15 | F30: 2023-09-09 | G30: 2023-09-09 | H30: 2023-09-11 | I30: 2023-09-11 | J30: 2023-09-11 | K30: 45169 | L30: 45187 | M30: 45187 | N30: 2023-09-20 | O30: 2023-09-20 | P30: 2023-09-20 | Q30: 2023-09-20
A31: 45138 | B31: 2023-08-15 | C31: 2023-08-15 | D31: 2023-08-15 | E31: 2023-08-15 | F31: 2023-08-09 | G31: 2023-08-09 | H31: 2023-08-11 | I31: 2023-08-11 | J31: 2023-08-11 | K31: 45138 | L31: 45156 | M31: 45156 | N31: 2023-08-20 | O31: 2023-08-20 | P31: 2023-08-20 | Q31: 2023-08-20
A32: 45107 | B32: 2023-07-17 | C32: 2023-07-17 | D32: 2023-07-17 | E32: 2023-07-17 | F32: 2023-07-10 | G32: 2023-07-10 | H32: 2023-07-11 | I32: 2023-07-11 | J32: 2023-07-11 | K32: 45107 | L32: 45125 | M32: 45125 | N32: 2023-07-20 | O32: 2023-07-20 | P32: 2023-07-20 | Q32: 2023-07-20
A33: 45077 | B33: 2023-06-15 | C33: 2023-06-15 | D33: 2023-06-15 | E33: 2023-06-15 | F33: 2023-06-09 | G33: 2023-06-09 | H33: 2023-06-13 | I33: 2023-06-13 | J33: 2023-06-13 | K33: 45077 | L33: 45095 | M33: 45095 | N33: 2023-06-20 | O33: 2023-06-20 | P33: 2023-06-20 | Q33: 2023-06-20
A34: 45046 | B34: 2023-05-16 | C34: 2023-05-16 | D34: 2023-05-16 | E34: 2023-05-16 | F34: 2023-05-11 | G34: 2023-05-11 | H34: 2023-05-11 | I34: 2023-05-11 | J34: 2023-05-11 | K34: 45046 | L34: 45064 | M34: 45064 | N34: 2023-05-20 | O34: 2023-05-20 | P34: 2023-05-20 | Q34: 2023-05-20
A35: 45016 | B35: 2023-04-18 | C35: 2023-04-18 | D35: 2023-04-18 | E35: 2023-04-18 | F35: 2023-04-11 | G35: 2023-04-11 | H35: 2023-04-11 | I35: 2023-04-11 | J35: 2023-04-11 | K35: 45016 | L35: 45034 | M35: 45034 | N35: 2023-04-20 | O35: 2023-04-20 | P35: 2023-04-20 | Q35: 2023-04-20
A36: 44985 | B36: 2023-03-15 | C36: 2023-03-15 | D36: 2023-03-15 | E36: 2023-03-15 | F36: 2023-03-09 | G36: 2023-03-09 | H36: 2023-03-10 | I36: 2023-03-10 | J36: 2023-03-10 | K36: 44986 | L36: 45003 | M36: 45003 | N36: 2023-03-20 | O36: 2023-03-20 | P36: 2023-03-20 | Q36: 2023-03-20
A37: 44957 | B37: 44944 | C37: 44944 | D37: 44944 | E37: 44944 | F37: 2023-02-10 | G37: 2023-02-10 | H37: 2023-02-10 | I37: 2023-02-10 | J37: 2023-02-10 | K37: 44957 | L37: 45003 | M37: 45003 | N37: 2023-02-20 | O37: 2023-02-20 | P37: 2023-02-20 | Q37: 2023-02-20
A38: 44926 | B38: 2023-01-17 | C38: 2023-01-17 | D38: 2023-01-17 | E38: 2023-01-17 | F38: 2023-01-12 | G38: 2023-01-12 | H38: 2023-01-10 | I38: 2023-01-10 | J38: 2023-01-10 | K38: 44926 | L38: 44944 | M38: 44944 | N38: 2023-01-20 | O38: 2023-01-20 | P38: 2023-01-20 | Q38: 2023-01-20
A39: 44895 | B39: 2022-12-15 | C39: 2022-12-15 | D39: 2022-12-15 | E39: 2022-12-15 | F39: 2022-12-09 | G39: 2022-12-09 | H39: 2022-12-12 | I39: 2022-12-12 | J39: 2022-12-12 | K39: 44895 | L39: 44913 | M39: 44913 | N39: 2022-12-20 | O39: 2022-12-20 | P39: 2022-12-20 | Q39: 2022-12-20
A40: 44865 | B40: 2022-11-15 | C40: 2022-11-15 | D40: 2022-11-15 | E40: 2022-11-15 | F40: 2022-11-09 | G40: 2022-11-09 | H40: 2022-11-10 | I40: 2022-11-10 | J40: 2022-11-10 | K40: 44865 | L40: 44883 | M40: 44883 | N40: 2022-11-20 | O40: 2022-11-20 | P40: 2022-11-20 | Q40: 2022-11-20
...

Sheet Sheet1
C1: 工业增加值同比
C2: 社会消费品零售总额同比
C3: 固定资产投资完成额:基础设施建设:累计同比
C4: 房地产开发投资完成额:累计同比
C5: CPI同比
C6: PPI同比
C7: 社融同比
C8: M1同比
C9: M2同比
C10: PMI-50
C11: 进口金额
C12: 出口金额
... C16: 保险托管同比

Sheet 滚动稳健标准化周频
B1: 中国:开工率:石油沥青装置:周:结束日5:前一个观测值 | C1: 中国:日均产量:粗钢:周:结束日5:前一个观测值 | D1: 唐山:高炉开工率:周:结束日5:前一个观测值 | E1: 中国:开工率:汽车轮胎(半钢胎):周:结束日5:前一个观测值 | F1: 中国:100大中城市:成交土地占地面积:当周值:周:结束日5:前一个观测值 | G1: 上海出口集装箱运价指数:综合指数:周:结束日5:前一个观测值
A2: 46045 | B2: 26.8 | C2: 244 | D2: 90.77 | E2: 74.56 | F2: 701.3603 | G2: 1457.86
A3: 46038 | B3: 27.2 | C3: 248 | D3: 90.77 | E3: 73.44 | F3: 874.8991 | G3: 1574.12
A4: 46031 | B4: 25.4 | C4: 202 | D4: 89.99 | E4: 65.89 | F4: 811.5168 | G4: 1647.39
A5: 46024 | B5: 27.4 | C5: 227 | D5: 93.64 | E5: 68.25 | F5: 1146.3192 | G5: 1656.32
A6: 46017 | B6: 31.3 | C6: 227 | D6: 93.64 | E6: 72.05 | F6: 3450.6099 | G6: 1656.32
A7: 46010 | B7: 27.6 | C7: 227 | D7: 92.71 | E7: 71.39 | F7: 4410.2299 | G7: 1552.92
A8: 46003 | B8: 27.8 | C8: 228 | D8: 91.8 | E8: 71.57 | F8: 4556.0992 | G8: 1506.46
A9: 45996 | B9: 27.9 | C9: 216 | D9: 93.51 | E9: 70.92 | F9: 2637.8166 | G9: 1397.63
A10: 45989 | B10: 27.8 | C10: 231 | D10: 91.08 | E10: 69.19 | F10: 2318.5822 | G10: 1403.13
A11: 45982 | B11: 24.8 | C11: 231 | D11: 91.2 | E11: 71.07 | F11: 2514.3444 | G11: 1393.56
A12: 45975 | B12: 29 | C12: 235 | D12: 91.2 | E12: 73.68 | F12: 1349.7759 | G12: 1451.38
A13: 45968 | B13: 29.7 | C13: 235 | D13: 91.87 | E13: 73.67 | F13: 627.567 | G13: 1495.1
... A557: 42160 | B557: 64 | C557: 222.82 | D557: 94.03 | E557: 74.7 | F557: 2099.1411 | G557: 623.47
A558: 42153 | C558: 222.82 | D558: 94.47 | E558: 75.03 | F558: 1790.5242 | G558: 661.55
A559: 42146 | C559: 228.5 | D559: 94.47 | E559: 74.6 | F559: 1817.4815 | G559: 676.05
A560: 42139 | C560: 226.9 | D560: 94.03 | E560: 73.73 | F560: 1722.0566 | G560: 757.66
A561: 42132 | C561: 226.9 | D561: 93.72 | E561: 72.65 | F561: 1203.7514 | G561: 830.13
A562: 42125 | C562: 235.14 | D562: 93.26 | E562: 72.14 | F562: 1044.421 | G562: 761.02
A563: 42118 | C563: 228.5 | D563: 94.01 | E563: 72.65 | F563: 1241.0576 | G563: 702.46
A564: 42111 | C564: 228.5 | D564: 94.01 | E564: 71.36 | F564: 799.2488 | G564: 721.61
A565: 42104 | C565: 225.7 | D565: 94.01 | E565: 70.7 | F565: 839.2069 | G565: 792.92
A566: 42097 | C566: 209.3 | D566: 92.45 | E566: 69.52 | F566: 1009.2706 | G566: 763.95
A567: 42090 | C567: 212.89 | D567: 90.64 | E567: 69.09 | F567: 977.0021 | G567: 804.59
A568: 42083 | C568: 212.89 | D568: 90.11 | E568: 67.21 | F568: 2417.7039 | G568: 821.39
A569: 42076 | C569: 219.68 | D569: 90.02 | E569: 63.48 | F569: 2351.5698 | G569: 887.61
... A633: 41628 | C633: 201.43 | D633: 91.93 | E633: 83 | F633: 5773.2322 | G633: 1115.29
A634: 41621 | C634: 201.29 | E634: 83 | F634: 5271.7945 | G634: 1117.3
A635: 41614 | C635: 209.1 | E635: 81.6 | F635: 3236.158 | G635: 970.85
A636: 41607 | C636: 209.1 | E636: 82 | F636: 3659.4169 | G636: 996.52
A637: 41600 | C637: 213.2 | E637: 84 | F637: 3116.6104 | G637: 1039.5
A638: 41593 | C638: 214.4 | E638: 83 | F638: 3263.6429 | G638: 1089.35
A639: 41586 | C639: 214.4 | E639: 82 | F639: 1973.7647 | G639: 1090.16
A640: 41579 | C640: 209.84 | E640: 84 | F640: 4520.2896 | G640: 1128.75
A641: 41572 | C641: 210.68 | E641: 83 | F641: 3386.7039 | G641: 892.47
A642: 41565 | C642: 210.68 | E642: 83 | F642: 3612.2993 | G642: 881.74
A643: 41558 | C643: 212.81 | E643: 83 | F643: 3148.7936 | G643: 894.41
A644: 41551 | C644: 215.2 | E644: 81.9 | F644: 609.8928 | G644: 936.89
A645: 41544 | C645: 215.2 | E645: 81.9 | F645: 5139.9758 | G645: 936.89
... A840: 40179 | C840: 165 | E840: 73.79 | F840: 2760.8009 | G840: 1072.58

Sheet 滚动稳健标准化日频
B1: DR001 | C1: DR007 | D1: R001 | E1: R007 | F1: 1Y存单发行利率 | G1: FR007:1年 | H1: 成交量:R001 | I1: R001成交量占比 | J1: 美元指数 | K1: 中间价 | L1: 即期汇率 | M1: 1年信用利差 | N1: 3年信用利差 | O1: 5年信用利差 | P1: 国债期货成交量：10年 | Q1: 国债期货持仓量:10年 | R1: 国债期货收盘价(活跃合约):10年 | S1: 票房收入 | T1: 30城商品房成交面积 | U1: 精对苯二甲酸开工率 | V1: PTA负荷率 | W1: 玻璃市场价 | X1: 波罗的海 | Y1: 秦皇岛港口吞吐量 | Z1: 期货结算价(活跃合约):焦煤 | AA1: 期货结算价(活跃合约):螺纹钢 | AB1: 水泥价格指数 | AC1: 南华工业品指数 | AD1: 2年美债 | AE1: 10年美债 | AF1: 道琼斯 | AG1: 标普500 | AH1: 纳斯达克 | AI1: 沪深300 | AJ1: 上证综指 | AK1: 科创50 | AL1: 恒生科技 | AM1: COMEX金价 | AN1: 阴极铜价格 | AO1: ICE布油 | AP1: 股债相对 | AQ1: 债券净融资 | AR1: 净买入：券商自营 | AS1: 净买入：保险 | AT1: 净买入：基金 | AU1: 净买入：理财 | AV1: 净买入：货币基金 | AW1: 十年国债活跃券成交量
A2: 46050 | B2: 1.367 | C2: 1.5479 | D2: 1.4381 | E2: 1.6122 | F2: 1.6623 | G2: 1.5113 | H2: 69529.542 | I2: 0.86613942 | J2: 96.352 | K2: 6.9755 | L2: 6.9453 | M2: 14.5 | N2: 20.32 | O2: 28.96 | P2: 63228 | Q2: 285206 | R2: 108.21 | S2: 2962.21 | T2: 23.458495 | U2: 75.83 | V2: 75.86 | W2: 1139.7 | X2: 2016 | Y2: 52.3 | Z2: 1121 | AA2: 3122 | AB2: 98.91 | AC2: 3705.54 | AD2: 3.56 | AE2: 4.26 | AF2: 49015.6 | AG2: 6978.03 | AH2: 23857.45 | AI2: 4717.9914 | AJ2: 4151.2378 | AK2: 1554.8037 | AL2: 5900.16 | AM2: 5411 | AN2: 103060 | AO2: 67.69 | AP2: 1.4088857 | AQ2: 541.58469 | AR2: -189.85 | AS2: -16.19 | AT2: -188.53 | AU2: 17.87 | AV2: -90.54 | AW2: 30900
A3: 46049 | B3: 1.3674 | C3: 1.5833 | D3: 1.4492 | E3: 1.6291 | F3: 1.7014 | G3: 1.5081 | H3: 72140.532 | I3: 0.86716405 | J3: 95.7725 | K3: 6.9858 | L3: 6.9576 | M3: 14.21 | N3: 19.62 | O3: 27.63 | P3: 63355 | Q3: 283423 | R3: 108.185 | S3: 2837.54 | T3: 18.63719 | U3: 75.83 | V3: 75.86 | W3: 1139.7 | X3: 1999 | Y3: 51.7 | Z3: 1129.5 | AA3: 3133 | AB3: 99.21 | AC3: 3660.54 | AD3: 3.53 | AE3: 4.24 | AF3: 49003.41 | AG3: 6978.6 | AH3: 23817.1 | AI3: 4705.6918 | AJ3: 4139.9041 | AK3: 1555.9783 | AL3: 5754.72 | AM3: 5179.6 | AN3: 102600 | AO3: 66.76 | AP3: 1.4036918 | AQ3: 3156.5098 | AR3: -328.3 | AS3: 73.99 | AT3: -81.43 | AU3: 55.9 | AV3: -112.04 | AW3: 29200
A4: 46048 | B4: 1.4174 | C4: 1.5738 | D4: 1.4898 | E4: 1.6245 | F4: 1.6479 | G4: 1.503 | H4: 73452.027 | I4: 0.86906572 | J4: 97.0506 | K4: 6.9843 | L4: 6.9572 | M4: 14.78 | N4: 20.99 | O4: 27.58 | P4: 68194 | Q4: 280314 | R4: 108.18 | S4: 2868.59 | T4: 17.180802 | U4: 75.83 | V4: 75.86 | W4: 1139.7 | X4: 1780 | Y4: 45.3 | Z4: 1151 | AA4: 3151 | AB4: 99.38 | AC4: 3689.42 | AD4: 3.56 | AE4: 4.22 | AF4: 49412.4 | AG4: 6950.23 | AH4: 23601.357 | AI4: 4706.964 | AJ4: 4132.6052 | AK4: 1532.796 | AL4: 5725.99 | AM4: 5004.8 | AN4: 101880 | AO4: 64.9 | AP4: 1.4080693 | AQ4: 1571.4509 | AR4: -78.81 | AS4: 5.24 | AT4: 288.58 | AU4: 13.07 | AV4: 249.6 | AW4: 21800
A5: 46047 | B5: 1.3983 | C5: 1.4935 | D5: 1.4654 | E5: 1.536 | F5: 1.6982 | G5: 1.5 | H5: 75804.152 | I5: 0.91708349 | J5: 97.5053 | K5: 6.9929 | L5: 6.9642 | M5: 14.62 | N5: 22.49 | O5: 28.05 | P5: 77051 | Q5: 279387 | R5: 108.195 | S5: 6583.28 | T5: 13.015356 | U5: 75.83 | V5: 75.86 | W5: 1139.7 | X5: 1762 | Y5: 46.1 | Z5: 1144 | AA5: 3134 | AB5: 99.62 | AC5: 3660.83 | AD5: 3.6 | AE5: 4.24 | AF5: 49098.71 | AG5: 6915.61 | AH5: 23501.24 | AI5: 4702.4966 | AJ5: 4136.1642 | AK5: 1553.7073 | AL5: 5798.01 | AM5: 4983.1 | AN5: 101340 | AO5: 65.44 | AP5: 1.4083506 | AQ5: -546.15
A6: 46046 | B6: 1.3983 | C6: 1.4935 | D6: 1.4654 | E6: 1.536 | F6: 1.6982 | G6: 1.5 | H6: 75804.152 | I6: 0.91708349 | J6: 97.5053 | K6: 6.9929 | L6: 6.9642 | M6: 14.62 | N6: 22.49 | O6: 28.05 | P6: 77051 | Q6: 279387 | R6: 108.195 | S6: 8542.73 | T6: 14.632958 | U6: 75.83 | V6: 75.86 | W6: 1139.7 | X6: 1762 | Y6: 50.4 | Z6: 1144 | AA6: 3134 | AB6: 99.62 | AC6: 3660.83 | AD6: 3.6 | AE6: 4.24 | AF6: 49098.71 | AG6: 6915.61 | AH6: 23501.24 | AI6: 4702.4966 | AJ6: 4136.1642 | AK6: 1553.7073 | AL6: 5798.01 | AM6: 4983.1 | AN6: 101340 | AO6: 65.44 | AP6: 1.4313586 | AQ6: -257
A7: 46045 | B7: 1.3983 | C7: 1.4935 | D7: 1.4654 | E7: 1.536 | F7: 1.6982 | G7: 1.5 | H7: 75804.152 | I7: 0.91708349 | J7: 97.5053 | K7: 6.9929 | L7: 6.9642 | M7: 14.62 | N7: 22.49 | O7: 28.05 | P7: 77051 | Q7: 279387 | R7: 108.195 | S7: 5835.06 | T7: 20.008017 | U7: 75.83 | V7: 75.86 | W7: 1139.7 | X7: 1762 | Y7: 49.8 | Z7: 1144 | AA7: 3134 | AB7: 99.62 | AC7: 3660.83 | AD7: 3.6 | AE7: 4.24 | AF7: 49098.71 | AG7: 6915.61 | AH7: 23501.24 | AI7: 4702.4966 | AJ7: 4136.1642 | AK7: 1553.7073 | AL7: 5798.01 | AM7: 4983.1 | AN7: 101340 | AO7: 65.44 | AP7: 1.4684665 | AQ7: 2387.3605 | AR7: -113.79 | AS7: 119.34 | AT7: 0.63 | AU7: 32.62 | AV7: -85.35 | AW7: 26700
A8: 46044 | B8: 1.4171 | C8: 1.5074 | D8: 1.4822 | E8: 1.5473 | F8: 1.71 | G8: 1.5087 | H8: 76209.496 | I8: 0.90231415 | J8: 98.2778 | K8: 7.0019 | L8: 6.9628 | M8: 13.7 | N8: 21.88 | O8: 27.41 | P8: 51902 | Q8: 274115 | R8: 108.15 | S8: 2354.49 | T8: 18.73942 | U8: 75.83 | V8: 75.86 | W8: 1124.2 | X8: 1761 | Y8: 41.4 | Z8: 1125 | AA8: 3124 | AB8: 99.75 | AC8: 3624.02 | AD8: 3.61 | AE8: 4.26 | AF8: 49384.01 | AG8: 6913.35 | AH8: 23436.02 | AI8: 4723.7091 | AJ8: 4122.576 | AK8: 1541.638 | AL8: 5762.44 | AM8: 4938.4 | AN8: 100700 | AO8: 64.62 | AP8: 1.4500407 | AQ8: 2082.9928 | AR8: -308.44 | AS8: 147.66 | AT8: 252.28 | AU8: 67.51 | AV8: 91.29 | AW8: 13000
A9: 46043 | B9: 1.3212 | C9: 1.4952 | D9: 1.395 | E9: 1.5396 | F9: 1.6989 | G9: 1.5037 | H9: 79428.574 | I9: 0.90436783 | J9: 98.7693 | K9: 7.0014 | L9: 6.965 | M9: 13.15 | N9: 23.21 | O9: 29.27 | P9: 83496 | Q9: 272588 | R9: 108.2 | S9: 2395.37 | T9: 17.64838 | U9: 75.83 | V9: 75.86 | W9: 1124.2 | X9: 1803 | Y9: 44.6 | Z9: 1119.5 | AA9: 3113 | AB9: 99.92 | AC9: 3596.59 | AD9: 3.6 | AE9: 4.26 | AF9: 49077.23 | AG9: 6875.62 | AH9: 23224.82 | AI9: 4723.0692 | AJ9: 4116.94 | AK9: 1535.3934 | AL9: 5746.3 | AM9: 4836.2 | AN9: 101280 | AO9: 64.62 | AP9: 1.4587156 | AQ9: 2340.9651 | AR9: 133.08 | AS9: 78.05 | AT9: 414.88 | AU9: 14.2 | AV9: 0.7 | AW9: 36700
A10: 46042 | B10: 1.3712 | C10: 1.4948 | D10: 1.4212 | E10: 1.5429 | F10: 1.7274 | G10: 1.5051 | H10: 78171.836 | I10: 0.89889331 | J10: 98.5413 | K10: 7.0006 | L10: 6.9603 | M10: 13.42 | N10: 24.42 | O10: 31.16 | P10: 68508 | Q10: 267617 | R10: 108.18 | S10: 2360.53 | T10: 19.53622 | U10: 75.83 | V10: 75.86 | W10: 1124.2 | X10: 1729 | Y10: 44.8 | Z10: 1150 | AA10: 3128 | AB10: 99.98 | AC10: 3586.63 | AD10: 3.6 | AE10: 4.3 | AF10: 48488.59 | AG10: 6796.86 | AH10: 22954.32 | AI10: 4718.8782 | AJ10: 4113.649 | AK10: 1482.9941 | AL10: 5683.44 | AM10: 4769.1 | AN10: 101230 | AO10: 64 | AP10: 1.4572193 | AQ10: 122.7449 | AR10: -81.3 | AS10: 206.68 | AT10: 68.54 | AU10: 50.55 | AV10: -71.97 | AW10: 37700
A11: 46041 | B11: 1.3182 | C11: 1.4772 | D11: 1.3752 | E11: 1.5288 | F11: 1.7121 | G11: 1.5039 | H11: 77963.24 | I11: 0.90165598 | J11: 99.0423 | K11: 7.0051 | L11: 6.9636 | M11: 14.88 | N11: 24.68 | O11: 30.39 | P11: 57602 | Q11: 258387 | R11: 108.04 | S11: 2344.16 | T11: 16.040475 | U11: 75.83 | V11: 75.86 | W11: 1124.2 | X11: 1650 | Y11: 42 | Z11: 1177 | AA11: 3148 | AB11: 100.47 | AC11: 3604.8 | AD11: 3.59 | AE11: 4.24 | AF11: 49359.33 | AG11: 6940.01 | AH11: 23515.39 | AI11: 4734.4556 | AJ11: 4114.0001 | AK11: 1506.8571 | AL11: 5749.98 | AM11: 4601.1 | AN11: 101180 | AO11: 64.18 | AP11: 1.4514217 | AQ11: 2255.5053 | AR11: -132.26 | AS11: 215.94 | AT11: 264.2 | AU11: 12.51 | AV11: -193.48 | AW11: 14600
A12: 46040 | B12: 1.3199 | C12: 1.443 | D12: 1.3734 | E12: 1.5137 | F12: 1.7086 | G12: 1.4988 | H12: 80478.201 | I12: 0.91888155 | J12: 99.3691 | K12: 7.0078 | L12: 6.969 | M12: 15.44 | N12: 26.17 | O12: 31.14 | P12: 74124 | Q12: 259760 | R12: 108.065 | S12: 6015.85 | T12: 10.721303 | U12: 75.83 | V12: 75.86 | W12: 1124.2 | X12: 1567 | Y12: 51.3 | Z12: 1184 | AA12: 3173 | AB12: 100.49 | AC12: 3621.64 | AD12: 3.59 | AE12: 4.24 | AF12: 49359.33 | AG12: 6940.01 | AH12: 23515.39 | AI12: 4731.8728 | AJ12: 4101.9127 | AK12: 1514.0681 | AL12: 5822.18 | AM12: 4601.1 | AN12: 100770 | AO12: 64.2 | AP12: 1.4485997 | AQ12: -469.32701
A13: 46039 | B13: 1.3199 | C13: 1.443 | D13: 1.3734 | E13: 1.5137 | F13: 1.7086 | G13: 1.4988 | H13: 80478.201 | I13: 0.91888155 | J13: 99.3691 | K13: 7.0078 | L13: 6.969 | M13: 15.44 | N13: 26.17 | O13: 31.14 | P13: 74124 | Q13: 259760 | R13: 108.065 | S13: 7682.96 | T13: 12.056278 | U13: 75.83 | V13: 75.86 | W13: 1124.2 | X13: 1567 | Y13: 22.8 | Z13: 1184 | AA13: 3173 | AB13: 100.49 | AC13: 3621.64 | AD13: 3.59 | AE13: 4.24 | AF13: 49359.33 | AG13: 6940.01 | AH13: 23515.39 | AI13: 4731.8728 | AJ13: 4101.9127 | AK13: 1514.0681 | AL13: 5822.18 | AM13: 4601.1 | AN13: 100770 | AO13: 64.2 | AP13: 1.4496852 | AQ13: -369.64
A14: 46038 | B14: 1.3199 | C14: 1.443 | D14: 1.3734 | E14: 1.5137 | F14: 1.7086 | G14: 1.4988 | H14: 80478.201 | I14: 0.91888155 | J14: 99.3691 | K14: 7.0078 | L14: 6.969 | M14: 15.44 | N14: 26.17 | O14: 31.14 | P14: 74124 | Q14: 259760 | R14: 108.065 | S14: 3645.23 | T14: 20.14013 | U14: 75.83 | V14: 75.86 | W14: 1124.2 | X14: 1567 | Y14: 43 | Z14: 1184 | AA14: 3173 | AB14: 100.49 | AC14: 3621.64 | AD14: 3.59 | AE14: 4.24 | AF14: 49359.33 | AG14: 6940.01 | AH14: 23515.39 | AI14: 4731.8728 | AJ14: 4101.9127 | AK14: 1514.0681 | AL14: 5822.18 | AM14: 4601.1 | AN14: 100770 | AO14: 64.2 | AP14: 1.4496852 | AQ14: -1593.0804 | AR14: -251.23 | AS14: 235.24 | AT14: 187.68 | AU14: 22.23 | AV14: -108.59 | AW14: 29800
A15: 46037 | B15: 1.3672 | C15: 1.5024 | D15: 1.4154 | E15: 1.5497 | F15: 1.726 | G15: 1.5104 | H15: 80140.549 | I15: 0.91492584 | J15: 99.3424 | K15: 7.0064 | L15: 6.9698 | M15: 15.84 | N15: 26.15 | O15: 31.69 | P15: 91991 | Q15: 254914 | R15: 108.035 | S15: 2541.32 | T15: 23.4045 | U15: 76.76 | V15: 75.86 | W15: 1124.2 | X15: 1532 | Y15: 59.4 | Z15: 1188.5 | AA15: 3161 | AB15: 100.57 | AC15: 3672.4 | AD15: 3.56 | AE15: 4.17 | AF15: 49442.44 | AG15: 6944.47 | AH15: 23530.02 | AI15: 4751.4293 | AJ15: 4112.6012 | AK15: 1493.945 | AL15: 5828.35 | AM15: 4620.5 | AN15: 102810 | AO15: 63.87 | AP15: 1.4054681 | AQ15: -4632.2433 | AR15: -141.7 | AS15: 150.1 | AT15: -24.1 | AU15: 41.8 | AV15: -253.3 | AW15: 41200
A16: 46036 | B16: 1.392 | C16: 1.5668 | D16: 1.4913 | E16: 1.6037 | F16: 1.7135 | G16: 1.5232 | H16: 72499.29 | I16: 0.89386849 | J16: 99.0753 | K16: 7.012 | L16: 6.9734 | M16: 16.19 | N16: 26.84 | O16: 33.48 | P16: 84940 | Q16: 252823 | R16: 107.93 | S16: 2586.7 | T16: 18.393312 | U16: 76.76 | V16: 75.86 | W16: 1124.2 | X16: 1566 | Y16: 53.2 | Z16: 1199.5 | AA16: 3164 | AB16: 100.56 | AC16: 3680.51 | AD16: 3.51 | AE16: 4.15 | AF16: 49149.63 | AG16: 6926.6 | AH16: 23471.75 | AI16: 4741.9306 | AJ16: 4126.0932 | AK16: 1500.911 | AL16: 5908.26 | AM16: 4633.9 | AN16: 104120 | AO16: 65.39 | AP16: 1.4064021 | AQ16: 1991.9842 | AR16: -31.48 | AS16: 180.08 | AT16: -48.49 | AU16: 22.59 | AV16: -290.41 | AW16: 52700
A17: 46035 | B17: 1.3913 | C17: 1.5474 | D17: 1.4719 | E17: 1.5746 | F17: 1.7234 | G17: 1.5239 | H17: 76278.752 | I17: 0.89214609 | J17: 99.1842 | K17: 7.0103 | L17: 6.9765 | M17: 16.2 | N17: 26.58 | O17: 32.92 | P17: 58261 | Q17: 251204 | R17: 107.85 | S17: 2609.05 | T17: 20.120729 | U17: 77.41 | V17: 75.86 | W17: 1124.2 | X17: 1608 | Y17: 31.5 | Z17: 1215 | AA17: 3161 | AB17: 100.58 | AC17: 3651.95 | AD17: 3.53 | AE17: 4.18 | AF17: 49191.99 | AG17: 6963.74 | AH17: 23709.87 | AI17: 4761.0324 | AJ17: 4138.7585 | AK17: 1469.5699 | AL17: 5869.79 | AM17: 4594.4 | AN17: 102290 | AO17: 65.46 | AP17: 1.3898699 | AQ17: -315.31195 | AR17: -169.85 | AS17: 170.83 | AT17: -22.98 | AU17: 105.84 | AV17: -250.8 | AW17: 39800
A18: 46034 | B18: 1.327 | C18: 1.4902 | D18: 1.3895 | E18: 1.5249 | F18: 1.6925 | G18: 1.5115 | H18: 80679.937 | I18: 0.90260258 | J18: 98.8943 | K18: 7.0108 | L18: 6.9742 | M18: 15.82 | N18: 25.97 | O18: 32.57 | P18: 68816 | Q18: 249332 | R18: 107.845 | S18: 2977.56 | T18: 21.984487 | U18: 77.41 | V18: 75.86 | W18: 1124.2 | X18: 1659 | Y18: 46.8 | Z18: 1221.5 | AA18: 3158 | AB18: 100.87 | AC18: 3674.29 | AD18: 3.54 | AE18: 4.19 | AF18: 49590.2 | AG18: 6977.27 | AH18: 23733.9 | AI18: 4789.9155 | AJ18: 4165.287 | AK18: 1511.836 | AL18: 5863.2 | AM18: 4608.8 | AN18: 103800 | AO18: 64.3 | AP18: 1.3775626 | AQ18: 1608.2534 | AR18: 124.91 | AS18: 176.72 | AT18: 139.96 | AU18: 44.23 | AV18: -149.15 | AW18: 35300
A19: 46033 | B19: 1.2727 | C19: 1.4727 | D19: 1.348 | E19: 1.5157 | F19: 1.7034 | G19: 1.5073 | H19: 80887.952 | I19: 0.91689334 | J19: 99.1368 | K19: 7.0128 | L19: 6.9821 | M19: 16.59 | N19: 25.74 | O19: 32.72 | P19: 78508 | Q19: 251267 | R19: 107.765 | S19: 7755.54 | T19: 10.272454 | U19: 77.41 | V19: 75.86 | W19: 1124.2 | X19: 1688 | Y19: 44 | Z19: 1188 | AA19: 3146 | AB19: 101.44 | AC19: 3635.84 | AD19: 3.54 | AE19: 4.18 | AF19: 49504.07 | AG19: 6966.28 | AH19: 23671.35 | AI19: 4758.9221 | AJ19: 4120.426 | AK19: 1475.9676 | AL19: 5687.14 | AM19: 4518.4 | AN19: 101410 | AO19: 63.02 | AP19: 1.3598126 | AQ19: -2154.51
A20: 46032 | B20: 1.2727 | C20: 1.4727 | D20: 1.348 | E20: 1.5157 | F20: 1.7034 | G20: 1.5073 | H20: 80887.952 | I20: 0.91689334 | J20: 99.1368 | K20: 7.0128 | L20: 6.9821 | M20: 16.59 | N20: 25.74 | O20: 32.72 | P20: 78508 | Q20: 251267 | R20: 107.765 | S20: 9928.65 | T20: 12.637534 | U20: 77.41 | V20: 75.86 | W20: 1124.2 | X20: 1688 | Y20: 30.6 | Z20: 1188 | AA20: 3146 | AB20: 101.44 | AC20: 3635.84 | AD20: 3.54 | AE20: 4.18 | AF20: 49504.07 | AG20: 6966.28 | AH20: 23671.35 | AI20: 4758.9221 | AJ20: 4120.426 | AK20: 1475.9676 | AL20: 5687.14 | AM20: 4518.4 | AN20: 101410 | AO20: 63.02 | AP20: 1.3690768 | AQ20: -539.10548
A21: 46031 | B21: 1.2727 | C21: 1.4727 | D21: 1.348 | E21: 1.5157 | F21: 1.7034 | G21: 1.5073 | H21: 80887.952 | I21: 0.91689334 | J21: 99.1368 | K21: 7.0128 | L21: 6.9821 | M21: 16.59 | N21: 25.74 | O21: 32.72 | P21: 78508 | Q21: 251267 | R21: 107.765 | S21: 4750.67 | T21: 20.747488 | U21: 77.41 | V21: 75.86 | W21: 1132.5 | X21: 1688 | Y21: 39.2 | Z21: 1188 | AA21: 3146 | AB21: 101.44 | AC21: 3635.84 | AD21: 3.54 | AE21: 4.18 | AF21: 49504.07 | AG21: 6966.28 | AH21: 23671.35 | AI21: 4758.9221 | AJ21: 4120.426 | AK21: 1475.9676 | AL21: 5687.14 | AM21: 4518.4 | AN21: 101410 | AO21: 63.02 | AP21: 1.3690768 | AQ21: 2015.6134 | AR21: -98.87 | AS21: 178.99 | AT21: 82.43 | AU21: 19.67 | AV21: -47.56 | AW21: 94400
A22: 46030 | B22: 1.2695 | C22: 1.474 | D22: 1.3424 | E22: 1.5261 | F22: 1.7613 | G22: 1.5105 | H22: 81319.747 | I22: 0.910043 | J22: 98.864 | K22: 7.0197 | L22: 6.9807 | M22: 15.76 | N22: 26.01 | O22: 30.9 | P22: 82422 | Q22: 247814 | R22: 107.79 | S22: 3113.64 | T22: 16.963707 | U22: 77.41 | V22: 75.86 | W22: 1132.5 | X22: 1718 | Y22: 47.4 | Z22: 1204 | AA22: 3179 | AB22: 101.54 | AC22: 3603.79 | AD22: 3.49 | AE22: 4.19 | AF22: 49266.11 | AG22: 6921.46 | AH22: 23480.02 | AI22: 4737.6536 | AJ22: 4082.9788 | AK22: 1455.1729 | AL22: 5678.34 | AM22: 4487.9 | AN22: 101220 | AO22: 62.7 | AP22: 1.3690768 | AQ22: 603.60017 | AR22: -196.2 | AS22: 196.5 | AT22: -716.3 | AU22: 15.1 | AV22: 213.1 | AW22: 96300
A23: 46029 | B23: 1.2674 | C23: 1.4625 | D23: 1.3365 | E23: 1.5323 | F23: 1.7024 | G23: 1.5115 | H23: 79864.408 | I23: 0.90183443 | J23: 98.7426 | K23: 7.0187 | L23: 6.9912 | M23: 16.1 | N23: 24.05 | O23: 28.87 | P23: 94286 | Q23: 244065 | R23: 107.61 | S23: 3283.49 | T23: 18.78898 | U23: 77.41 | V23: 75.86 | W23: 1132.5 | X23: 1776 | Y23: 49.8 | Z23: 1136 | AA23: 3154 | AB23: 101.68 | AC23: 3657.23 | AD23: 3.47 | AE23: 4.15 | AF23: 48996.08 | AG23: 6920.93 | AH23: 23584.27 | AI23: 4776.6658 | AJ23: 4085.7723 | AK23: 1443.388 | AL23: 5738.52 | AM23: 4467.1 | AN23: 103410 | AO23: 60.39 | AP23: 1.4290972 | AQ23: 2667.031 | AR23: -306.45 | AS23: 149.78 | AT23: -1335.96 | AU23: 77.72 | AV23: 81.1 | AW23: 100100
A24: 46028 | B24: 1.2628 | C24: 1.4326 | D24: 1.3302 | E24: 1.493 | F24: 1.7166 | G24: 1.5096 | H24: 76100.988 | I24: 0.89303915 | J24: 98.5997 | K24: 7.0173 | L24: 6.9813 | M24: 16.25 | N24: 26.2 | O24: 30.42 | P24: 89378 | Q24: 244047 | R24: 107.7 | S24: 3473.11 | T24: 18.868596 | U24: 77.41 | V24: 75.86 | W24: 1132.5 | X24: 1830 | Y24: 50 | Z24: 1078 | AA24: 3098 | AB24: 101.72 | AC24: 3609.73 | AD24: 3.47 | AE24: 4.18 | AF24: 49462.08 | AG24: 6944.82 | AH24: 23547.17 | AI24: 4790.6938 | AJ24: 4083.6672 | AK24: 1429.3023 | AL24: 5825.26 | AM24: 4505.7 | AN24: 105320 | AO24: 60.51 | AP24: 1.4367731 | AQ24: -93.352284 | AR24: -391.54 | AS24: 114.44 | AT24: -975.48 | AU24: 9.26 | AV24: -55.77 | AW24: 107000
A25: 46027 | B25: 1.2624 | C25: 1.4312 | D25: 1.3315 | E25: 1.4861 | F25: 1.8 | G25: 1.5043 | H25: 65977.614 | I25: 0.88686873 | J25: 98.3291 | K25: 7.023 | L25: 6.9806 | M25: 15.6 | N25: 27.68 | O25: 33.53 | P25: 86423 | Q25: 239562 | R25: 107.855 | S25: 3906.22 | T25: 18.960583 | U25: 77.41 | V25: 75.86 | W25: 1132.5 | X25: 1851 | Y25: 54.3 | Z25: 1097 | AA25: 3113 | AB25: 102.24 | AC25: 3544.39 | AD25: 3.46 | AE25: 4.17 | AF25: 48977.18 | AG25: 6902.05 | AH25: 23395.82 | AI25: 4717.7457 | AJ25: 4023.4167 | AK25: 1403.4142 | AL25: 5741.63 | AM25: 4459.7 | AN25: 101350 | AO25: 61.77 | AP25: 1.4755166 | AQ25: 1382.402 | AR25: -291.14 | AS25: 24.87 | AT25: -201.94 | AU25: -79.58 | AV25: -141.42 | AW25: 71600
A26: 46026 | B26: 1.2419 | C26: 1.4286 | D26: 1.26 | E26: 1.4525 | F26: 1.855 | G26: 1.5025 | H26: 23494.355 | I26: 0.95674233 | J26: 98.4594 | K26: 7.0288 | L26: 6.989 | M26: 19.62 | N26: 30.21 | O26: 35.08 | P26: 99072 | Q26: 236119 | R26: 107.86 | S26: 5151.76 | T26: 16.224458 | U26: 77.41 | V26: 75.86 | W26: 1132.5 | X26: 1882 | Y26: 50.9 | Z26: 1115.5 | AA26: 3127 | AB26: 102.39 | AC26: 3549.74 | AD26: 3.47 | AE26: 4.19 | AF26: 48382.39 | AG26: 6858.47 | AH26: 23235.63 | AI26: 4629.9395 | AJ26: 3968.8401 | AK26: 1344.2002 | AL26: 5736.44 | AM26: 4341.9 | AN26: 98240 | AO26: 60.8 | AP26: 1.5072991 | AQ26: 137.05
A27: 46025 | B27: 1.3325 | C27: 1.9821 | D27: 1.4568 | E27: 2.1559 | F27: 1.855 | G27: 1.5029 | H27: 14784.273 | I27: 0.34939368 | J27: 98.4594 | K27: 7.0288 | L27: 6.989 | M27: 21.61 | N27: 29.41 | O27: 35.83 | P27: 99072 | Q27: 236119 | R27: 107.86 | S27: 13804.51 | T27: 5.810898 | U27: 76.24 | V27: 75.86 | W27: 1132.5 | X27: 1882 | Y27: 51.8 | Z27: 1115.5 | AA27: 3127 | AB27: 102.66 | AC27: 3549.74 | AD27: 3.47 | AE27: 4.19 | AF27: 48382.39 | AG27: 6858.47 | AH27: 23235.63 | AI27: 4629.9395 | AJ27: 3968.8401 | AK27: 1344.2002 | AL27: 5736.44 | AM27: 4341.9 | AN27: 98240 | AO27: 60.8 | AP27: 1.5035457 | AQ27: -297.15278
A28: 46024 | B28: 1.3325 | C28: 1.9821 | D28: 1.4568 | E28: 2.1559 | F28: 1.855 | G28: 1.5029 | H28: 14784.273 | I28: 0.34939368 | J28: 98.4594 | K28: 7.0288 | L28: 6.989 | M28: 21.61 | N28: 29.41 | O28: 35.83 | P28: 99072 | Q28: 236119 | R28: 107.86 | S28: 26384.35 | T28: 5.589372 | U28: 76.24 | V28: 75.86 | W28: 1132.5 | X28: 1882 | Y28: 52 | Z28: 1115.5 | AA28: 3127 | AB28: 102.66 | AC28: 3549.74 | AD28: 3.47 | AE28: 4.19 | AF28: 48382.39 | AG28: 6858.47 | AH28: 23235.63 | AI28: 4629.9395 | AJ28: 3968.8401 | AK28: 1344.2002 | AL28: 5736.44 | AM28: 4341.9 | AN28: 98240 | AO28: 60.8 | AP28: 1.5035457 | AQ28: -121.16
A29: 46023 | B29: 1.3325 | C29: 1.9821 | D29: 1.4568 | E29: 2.1559 | F29: 1.855 | G29: 1.5029 | H29: 14784.273 | I29: 0.34939368 | J29: 98.249 | K29: 7.0288 | L29: 6.989 | M29: 21.61 | N29: 29.41 | O29: 35.83 | P29: 99072 | Q29: 236119 | R29: 107.86 | S29: 33780.57 | T29: 8.526592 | U29: 76.24 | V29: 75.86 | W29: 1132.5 | X29: 1877 | Y29: 41.1 | Z29: 1115.5 | AA29: 3127 | AB29: 102.66 | AC29: 3549.74 | AD29: 3.47 | AE29: 4.18 | AF29: 48063.29 | AG29: 6845.5 | AH29: 23241.99 | AI29: 4629.9395 | AJ29: 3968.8401 | AK29: 1344.2002 | AL29: 5515.98 | AM29: 4332.1 | AN29: 98240 | AO29: 60.91 | AP29: 1.5035457 | AQ29: -4.4
A30: 46022 | B30: 1.3325 | C30: 1.9821 | D30: 1.4568 | E30: 2.1559 | F30: 1.855 | G30: 1.5029 | H30: 14784.273 | I30: 0.34939368 | J30: 98.2696 | K30: 7.0288 | L30: 6.989 | M30: 21.61 | N30: 29.41 | O30: 35.83 | P30: 99072 | Q30: 236119 | R30: 107.86 | S30: 21130.4 | T30: 72.300309 | U30: 76.24 | V30: 75.86 | W30: 1132.5 | X30: 1877 | Y30: 47.6 | Z30: 1115.5 | AA30: 3127 | AB30: 102.66 | AC30: 3549.74 | AD30: 3.47 | AE30: 4.18 | AF30: 48063.29 | AG30: 6845.5 | AH30: 23241.99 | AI30: 4629.9395 | AJ30: 3968.8401 | AK30: 1344.2002 | AL30: 5515.98 | AM30: 4332.1 | AN30: 98240 | AO30: 60.91 | AP30: 1.5035457 | AQ30: -880.88499 | AR30: -315.49 | AS30: 129.55 | AT30: 280.87 | AU30: 44.89 | AV30: -177.96 | AW30: 38100
A31: 46021 | B31: 1.2395 | C31: 1.6874 | D31: 1.3782 | E31: 2.062 | F31: 1.64 | G31: 1.5003 | H31: 46068.609 | I31: 0.73376175 | J31: 98.2181 | K31: 7.0348 | L31: 6.9901 | M31: 22.17 | N31: 27.54 | O31: 36.49 | P31: 76849 | Q31: 242485 | R31: 107.94 | S31: 3679.1 | T31: 68.045113 | U31: 73.6 | V31: 75.86 | W31: 1153.1 | X31: 1877 | Y31: 53.3 | Z31: 1110 | AA31: 3137 | AB31: 102.38 | AC31: 3561.07 | AD31: 3.45 | AE31: 4.14 | AF31: 48367.06 | AG31: 6896.24 | AH31: 23419.08 | AI31: 4651.2818 | AJ31: 3965.1159 | AK31: 1359.8734 | AL31: 5578.38 | AM31: 4352.3 | AN31: 98090 | AO31: 61.28 | AP31: 1.4968787 | AQ31: -1904.6373 | AR31: -658.53 | AS31: 206.08 | AT31: 152.44 | AU31: 18.31 | AV31: -336.29 | AW31: 26600
A32: 46020 | B32: 1.2417 | C32: 1.5944 | D32: 1.3376 | E32: 1.936 | F32: 1.7679 | G32: 1.4978 | H32: 61077.193 | I32: 0.80160476 | J32: 97.9975 | K32: 7.0331 | L32: 7.0098 | M32: 23.27 | N32: 28.11 | O32: 37.46 | P32: 125650 | Q32: 247291 | R32: 107.975 | S32: 3410.02 | T32: 49.922603 | U32: 72.84 | V32: 75.86 | W32: 1153.1 | X32: 1877 | Y32: 57.1 | Z32: 1108.5 | AA32: 3137 | AB32: 102.38 | AC32: 3534.24 | AD32: 3.45 | AE32: 4.12 | AF32: 48461.93 | AG32: 6905.74 | AH32: 23474.35 | AI32: 4639.3721 | AJ32: 3965.2796 | AK32: 1346.3188 | AL32: 5483.01 | AM32: 4350.2 | AN32: 98860 | AO32: 61.26 | AP32: 1.4995157 | AQ32: 355.90133 | AR32: -226.02 | AS32: 13.87 | AT32: 371.36 | AU32: 62 | AV32: 33.18 | AW32: 52000
A33: 46019
A34: 46018
A35: 46017 | AR35: -155.28 | AS35: 11.19 | AT35: 423.46 | AU35: 32.05 | AV35: -218.1 | AW35: 30500
A36: 46016 | B36: 1.2589 | C36: 1.4842 | D36: 1.3559 | E36: 1.5245 | F36: 1.7845 | G36: 1.4875 | H36: 74364.354 | I36: 0.87095749 | J36: 97.9079 | K36: 7.0392 | L36: 7.0066 | M36: 24.3 | N36: 26.47 | O36: 35.53 | P36: 58691 | Q36: 258693 | R36: 108.195 | S36: 5422.05 | T36: 36.78298 | U36: 75.24 | V36: 75.86 | W36: 1153.1 | X36: 1877 | Y36: 58 | Z36: 1127 | AA36: 3131 | AB36: 102.46 | AC36: 3533.48 | AD36: 3.47 | AE36: 4.15 | AF36: 48731.16 | AG36: 6932.05 | AH36: 23613.31 | AI36: 4642.5357 | AJ36: 3959.6211 | AK36: 1349.0577 | AL36: 5499.3 | AM36: 4505.4 | AN36: 96210 | AO36: 61.84 | AP36: 1.5196889 | AQ36: -1511.1207 | AR36: 163 | AS36: -8.9 | AT36: 231.9 | AU36: -49.4 | AV36: 29.3 | AW36: 34400
A37: 46015 | B37: 1.2622 | C37: 1.38 | D37: 1.3568 | E37: 1.5198 | F37: 1.72 | G37: 1.4885 | H37: 77935.849 | I37: 0.89188692 | J37: 97.9535 | K37: 7.0471 | L37: 7.0161 | M37: 21.27 | N37: 27.31 | O37: 36.8 | P37: 73502 | Q37: 254485 | R37: 108.23 | S37: 5520.63 | T37: 42.552236 | U37: 75.24 | V37: 75.86 | W37: 1153.1 | X37: 1877 | Y37: 55.4 | Z37: 1124 | AA37: 3126 | AB37: 102.75 | AC37: 3543.43 | AD37: 3.47 | AE37: 4.15 | AF37: 48731.16 | AG37: 6932.05 | AH37: 23613.31 | AI37: 4634.0586 | AJ37: 3940.947 | AK37: 1352.1261 | AL37: 5499.3 | AM37: 4505.4 | AN37: 96100 | AO37: 61.84 | AP37: 1.5165613 | AQ37: =VLOOKUP(A37,[1]净融资函数!$B:$E,4,0) -> 1166.9123 | AR37: 224.3 | AS37: -44.8 | AT37: 234.1 | AU37: 18.4 | AV37: -227.4 | AW37: 34400
A38: 46014 | B38: 1.2691 | C38: 1.4105 | D38: 1.3542 | E38: 1.5028 | F38: 1.7668 | G38: 1.4857 | H38: 77084.354 | I38: 0.88763336 | J38: 97.9093 | K38: 7.0523 | L38: 7.0287 | M38: 20.74 | N38: 27.78 | O38: 39.1 | P38: 103305 | Q38: 252339 | R38: 108.22 | S38: 4776.4 | T38: 58.274063 | U38: 73.81 | V38: 75.86 | W38: 1153.1 | X38: 1889 | Y38: 48 | Z38: 1125 | AA38: 3134 | AB38: 102.78 | AC38: 3507.98 | AD38: 3.48 | AE38: 4.18 | AF38: 48442.41 | AG38: 6909.79 | AH38: 23561.84 | AI38: 4620.7341 | AJ38: 3919.9786 | AK38: 1340.015 | AL38: 5488.89 | AM38: 4515 | AN38: 93930 | AO38: 61.92 | AP38: 1.5180362 | AQ38: =VLOOKUP(A38,[1]净融资函数!$B:$E,4,0) -> -35.626754 | AR38: -123.4 | AS38: 122.3 | AT38: -148.4 | AU38: 70.1 | AV38: -142.3 | AW38: 40300
A39: 46013 | B39: 1.2705 | C39: 1.4337 | D39: 1.3547 | E39: 1.5063 | F39: 1.7465 | G39: 1.493 | H39: 76288.773 | I39: 0.88931548 | J39: 98.2603 | K39: 7.0572 | L39: 7.0382 | M39: 19.16 | N39: 27.22 | O39: 38.68 | P39: 88663 | Q39: 236558 | R39: 107.98 | S39: 5549.8 | T39: 42.440886 | U39: 73.81 | V39: 75.86 | W39: 1153.1 | X39: 1979 | Y39: 35.7 | Z39: 1104.5 | AA39: 3122 | AB39: 102.9 | AC39: 3493.62 | AD39: 3.44 | AE39: 4.17 | AF39: 48362.68 | AG39: 6878.49 | AH39: 23428.83 | AI39: 4611.6235 | AJ39: 3917.3638 | AK39: 1335.2451 | AL39: 5526.83 | AM39: 4480.6 | AN39: 94320 | AO39: 61.54 | AP39: 1.5152865 | AQ39: =VLOOKUP(A39,[1]净融资函数!$B:$E,4,0) -> 718.99911 | AR39: -122.8 | AS39: -64.9 | AT39: 425.4 | AU39: 98.8 | AV39: 153.9 | AW39: 34600
A40: 46012 | B40: 1.2706 | C40: 1.4413 | D40: 1.3517 | E40: 1.5148 | F40: 1.7898 | G40: 1.4929 | H40: 77283.041 | I40: 0.90341443 | J40: 98.7125 | K40: 7.055 | L40: 7.041 | M40: 19.65 | N40: 28.14 | O40: 40.17 | P40: 58808 | Q40: 240925 | R40: 108.15 | S40: 19846.27 | T40: 26.372704 | U40: 73.81 | V40: 75.86 | W40: 1153.1 | X40: 2023 | Y40: 45.9 | Z40: 1110 | AA40: 3114 | AB40: 102.94 | AC40: 3460.46 | AD40: 3.48 | AE40: 4.16 | AF40: 48134.89 | AG40: 6834.5 | AH40: 23307.62 | AI40: 4568.1781 | AJ40: 3890.4475 | AK40: 1308.5889 | AL40: 5479.04 | AM40: 4368.7 | AN40: 93180 | AO40: 60.12 | AP40: 1.5349574 | AQ40: =VLOOKUP(A40,[1]净融资函数!$B:$E,4,0) -> -315.90899
...

Sheet Sheet2
A1: =[2]!edb() -> Wind
A2: 指标名称 | B2: 上证科创板50成份指数 | C2: 恒生科技指数 | D2: 期货收盘价(连续):COMEX黄金 | E2: 中国:现货领先价格:阴极铜 | F2: 全球:现货价:原油(英国布伦特Dtd) | G2: 期货成交量:国债期货:10年期
A3: 27396 | B3: 0 | C3: 0 | D3: 175.1 | E3: 0 | F3: 0 | G3: 0
A4: 27397 | B4: 0 | C4: 0 | D4: 174.7 | E4: 0 | F4: 0 | G4: 0
A5: 27400 | B5: 0 | C5: 0 | D5: 174.4 | E5: 0 | F5: 0 | G5: 0
A6: 27401 | B6: 0 | C6: 0 | D6: 173.4 | E6: 0 | F6: 0 | G6: 0
A7: 27402 | B7: 0 | C7: 0 | D7: 177.4 | E7: 0 | F7: 0 | G7: 0 | K7: =(69-61)/61 -> 0.13114754
A8: 27403 | B8: 0 | C8: 0 | D8: 178.3 | E8: 0 | F8: 0 | G8: 0
A9: 27404 | B9: 0 | C9: 0 | D9: 181.3 | E9: 0 | F9: 0 | G9: 0
A10: 27407 | B10: 0 | C10: 0 | D10: 178.6 | E10: 0 | F10: 0 | G10: 0
A11: 27408 | B11: 0 | C11: 0 | D11: 178.6 | E11: 0 | F11: 0 | G11: 0
A12: 27409 | B12: 0 | C12: 0 | D12: 177.3 | E12: 0 | F12: 0 | G12: 0
A13: 27410 | B13: 0 | C13: 0 | D13: 175.1 | E13: 0 | F13: 0 | G13: 0
A14: 27411 | B14: 0 | C14: 0 | D14: 172.1 | E14: 0 | F14: 0 | G14: 0
A15: 27414 | B15: 0 | C15: 0 | D15: 176.2 | E15: 0 | F15: 0 | G15: 0
A16: 27415 | B16: 0 | C16: 0 | D16: 173.7 | E16: 0 | F16: 0 | G16: 0
A17: 27416 | B17: 0 | C17: 0 | D17: 174.3 | E17: 0 | F17: 0 | G17: 0
A18: 27417 | B18: 0 | C18: 0 | D18: 176.4 | E18: 0 | F18: 0 | G18: 0
A19: 27418 | B19: 0 | C19: 0 | D19: 179.5 | E19: 0 | F19: 0 | G19: 0
... A12958: 46063 | B12958: 1471.4978 | C12958: 5451.03 | D12958: 0 | E12958: 101734 | F12958: 0 | G12958: 105722

Sheet Sheet3
A1: 指标名称 | B1: 上证科创板50成份指数 | C1: 恒生科技指数 | D1: 期货收盘价(连续):COMEX黄金 | E1: 中国:现货领先价格:阴极铜 | F1: 全球:现货价:原油(英国布伦特Dtd) | G1: 期货成交量:国债期货:10年期
A2: 44418 | B2: 1588.1948 | C2: 6830.15 | D2: 1727.9 | E2: 0 | F2: 71.98 | G2: 85360
A3: 44419 | B3: 1578.7892 | C3: 6820.68 | D3: 1750.7 | E3: 0 | F3: 70.87 | G3: 80028
A4: 44420 | B4: 1586.5006 | C4: 6719.19 | D4: 1751.4 | E4: 0 | F4: 71.74 | G4: 79937
A5: 44421 | B5: 1552.7807 | C5: 6589.54 | D5: 1777.3 | E5: 0 | F5: 71.67 | G5: 92034
A6: 44424 | B6: 1547.931 | C6: 6420.14 | D6: 1786.4 | E6: 0 | F6: 70.2 | G6: 106961
A7: 44425 | B7: 1509.2474 | C7: 6218.89 | D7: 1783 | E7: 0 | F7: 70.65 | G7: 90919
A8: 44426 | B8: 1507.9886 | C8: 6226.69 | D8: 1787.2 | E8: 0 | F8: 69.85 | G8: 111209
A9: 44427 | B9: 1546.11 | C9: 6044.03 | D9: 1780.9 | E9: 0 | F9: 66.19 | G9: 90701
A10: 44428 | B10: 1529.0863 | C10: 5895.06 | D10: 1781.6 | E10: 0 | F10: 66.73 | G10: 66131
A11: 44431 | B11: 1564.1108 | C11: 6021.27 | D11: 1804.5 | E11: 0 | F11: 69.13 | G11: 60038
A12: 44432 | B12: 1578.0306 | C12: 6446.18 | D12: 1803.5 | E12: 0 | F12: 71.12 | G12: 63844
A13: 44433 | B13: 1542.7755 | C13: 6458.97 | D13: 1788.4 | E13: 0 | F13: 71.41 | G13: 66875
... A1172: 46063 | B1172: 1471.4978 | C1172: 5451.03 | D1172: 0 | E1172: 101734 | F1172: 0 | G1172: 105722

Sheet 差值历史稳健标准化
B1: 逆回购利率:7天 | C1: 存款准备金率:中小金融机构(变动公告日期)
A2: 46050 | B2: 1.4 | C2: 6
A3: 46049 | B3: 1.4 | C3: 6
A4: 46048 | B4: 1.4 | C4: 6
A5: 46047 | B5: 1.4 | C5: 6
A6: 46046 | B6: 1.4 | C6: 6
A7: 46045 | B7: 1.4 | C7: 6
A8: 46044 | B8: 1.4 | C8: 6
A9: 46043 | B9: 1.4 | C9: 6
A10: 46042 | B10: 1.4 | C10: 6
A11: 46041 | B11: 1.4 | C11: 6
A12: 46040 | B12: 1.4 | C12: 6
A13: 46039 | B13: 1.4 | C13: 6
... A5867: 40179 | B5867: 3.7561 | C5867: 13.5

Sheet 时代变量
B1: 中国各领导人时期 | C1: 美国各总统时期 | D1: 基本面主题变量
A2: 46050 | B2: 2 | C2: 5 | D2: 4
A3: 46049 | B3: 2 | C3: 5 | D3: 4
A4: 46048 | B4: 2 | C4: 5 | D4: 4
A5: 46047 | B5: 2 | C5: 5 | D5: 4
A6: 46046 | B6: 2 | C6: 5 | D6: 4
A7: 46045 | B7: 2 | C7: 5 | D7: 4
A8: 46044 | B8: 2 | C8: 5 | D8: 4
A9: 46043 | B9: 2 | C9: 5 | D9: 4
A10: 46042 | B10: 2 | C10: 5 | D10: 4
A11: 46041 | B11: 2 | C11: 5 | D11: 4
A12: 46040 | B12: 2 | C12: 5 | D12: 4
A13: 46039 | B13: 2 | C13: 5 | D13: 4
... A5867: 40179 | B5867: 1 | C5867: 1 | D5867: 1

Sheet 时代变量整理明细
A1: 时间 | B1: 中国 | D1: 美国 | F1: 基本面主题变量
B2: 形成共识时间 | C2: 正式当选时间 | D2: 形成共识时间 | E2: 领导人换届时间
A3: 2012 | B3: 2012.11.15 中共十八届一中全会 确认习近平当选中共中央总书记 | D3: 2012.11.7 奥巴马选举结果确定
A4: 2013 | C4: 2013.3.14 十二届全国人大 习近平正式当选国家主席 | E4: 2013.1.20 奥巴马正式就任
A5: 2014 | F5: 2014.9.12 中央经济工作会议 经济进入“新常态”
A6: 2015 | F6: 2015.12.21 中央经济工作会议 供给侧结构性改革
A7: 2016 | D7: 2016.11.8 特朗普选举结果确定 | F7: 2016.12.16 中央经济工作会议 “房住不炒”，地产转向
A8: 2017 | E8: 2017.1.20 特朗普正式就任 | F8: 2017.10.8 十九届全国人大 高速发展→高质量发展
A9: 2018 | F9: 2018.3.22 中美贸易战
A10: 2019 | F10: 2019.12.8 新冠疫情
A11: 2020 | D11: 2020.11.7 拜登选举结果确定
A12: 2021 | E12: 2021.1.20 拜登正式就任
A13: 2022 | F13: 2022.12.9 疫后复苏
A14: 2024 | D14: 2024.11.6 特朗普选举结果确定
A15: 2025 | E15: 2025.1.20（即将） 特朗普正式就任

Sheet 切券时间
A1: 切券起始日 | B1: 切券截止日
A2: 45502
A3: 45377 | B3: 45499
A4: 45285 | B4: 45376
A5: 45189 | B5: 45282
A6: 45090 | B6: 45188
A7: 44999 | B7: 45089
A8: 44916 | B8: 44998
A9: 44844 | B9: 44915
A10: 44823 | B10: 44843
A11: 44725 | B11: 44820
A12: 44642 | B12: 44722
A13: 44545 | B13: 44641
A14: 44382 | B14: 44544
... A54: 40386 | B54: 40448
